Workbook
Name Slicer_Covid_Period: #N/A
Name Slicer_Year: #N/A

Sheet CPI
A1: Sector | B1: Year | C1: Month | D1: Date | E1: Covid Period | F1: Cereals and products | G1: Meat and fish | H1: Egg | I1: Milk and products | J1: Oils and fats | K1: Fruits | L1: Vegetables | M1: Pulses and products | N1: Sugar and Confectionery | O1: Spices | P1: Non-alcoholic beverages | Q1: Prepared meals, snacks, sweets etc. | R1: Food and beverages | S1: Pan, tobacco and intoxicants | T1: Clothing | U1: Footwear | V1: Clothing and footwear | W1: Housing | X1: Fuel and light | Y1: Household goods and services | Z1: Health | AA1: Transport and communication | AB1: Recreation and amusement | AC1: Education | AD1: Personal care and effects | AE1: Miscellaneous | AF1: General index | AG1: Month Number
A2: Rural | B2: 2013 | C2: January | D2: =DATE(All_India_Index_Upto_April23__13[[#This Row],[Year]],All_India_Index_Upto_April23__13[[#This Row],[Month Number]],1) -> 41275 | E2: =IF(All_India_Index_Upto_April23__13[[#This Row],[Date]]<DATE(2020, 3, 1),"Pre-COVID","Post-COVID") -> Pre-COVID | F2: 107.5 | G2: 106.3 | H2: 108.1 | I2: 104.9 | J2: 106.1 | K2: 103.9 | L2: 101.9 | M2: 106.1 | N2: 106.8 | O2: 103.1 | P2: 104.8 | Q2: 106.7 | R2: 105.5 | S2: 105.1 | T2: 106.5 | U2: 105.8 | V2: 106.4 | W2: 141 | X2: 105.5 | Y2: 104.8 | Z2: 104 | AA2: 103.3 | AB2: 103.4 | AC2: 103.8 | AD2: 104.7 | AE2: 104 | AF2: 105.1 | AG2: =IF(All_India_Index_Upto_April23__13[[#This Row],[Month]] = "January", 1,IF(All_India_Index_Upto_April23__13[[#This Row],[Month]]="February",2,IF(All_India_Index_Upto_April23__13[[#This Row],[Month]]="March",3,IF(All_India_Index_Upto_April23__13[[#This Row],[Month]]="Marcrh",3,IF(All_India_Index_Upto_April23__13[[#This Row],[Month]]="April",4,IF(All_India_Index_Upto_April23__13[[#This Row],[Month]]="May",5,IF(All_India_Index_Upto_April23__13[[#This Row],[Month]]="June",6,IF(All_India_Index_Upto_April23__13[[#This Row],[Month]]="July",7,IF(All_India_Index_Upto_April23__13[[#This Row],[Month]]="August",8,IF(All_India_Index_Upto_April23__13[[#This Row],[Month]]="September",9,IF(All_India_Index_Upto_April23__13[[#This Row],[Month]]="October",10,IF(All_India_Index_Upto_April23__13[[#This Row],[Month]]="November",11,IF(All_India_Index_Upto_April23__13[[#This Row],[Month]]="December",12))))))))))))) -> 1
A3: Urban | B3: 2013 | C3: January | D3: =DATE(All_India_Index_Upto_April23__13[[#This Row],[Year]],All_India_Index_Upto_April23__13[[#This Row],[Month Number]],1) -> 41275 | E3: =IF(All_India_Index_Upto_April23__13[[#This Row],[Date]]<DATE(2020, 3, 1),"Pre-COVID","Post-COVID") -> Pre-COVID | F3: 110.5 | G3: 109.1 | H3: 113 | I3: 103.6 | J3: 103.4 | K3: 102.3 | L3: 102.9 | M3: 105.8 | N3: 105.1 | O3: 101.8 | P3: 105.1 | Q3: 107.9 | R3: 105.9 | S3: 105.2 | T3: 105.9 | U3: 105 | V3: 105.8 | W3: 100.3 | X3: 105.4 | Y3: 104.8 | Z3: 104.1 | AA3: 103.2 | AB3: 102.9 | AC3: 103.5 | AD3: 104.3 | AE3: 103.7 | AF3: 104 | AG3: =IF(All_India_Index_Upto_April23__13[[#This Row],[Month]] = "January", 1,IF(All_India_Index_Upto_April23__13[[#This Row],[Month]]="February",2,IF(All_India_Index_Upto_April23__13[[#This Row],[Month]]="March",3,IF(All_India_Index_Upto_April23__13[[#This Row],[Month]]="Marcrh",3,IF(All_India_Index_Upto_April23__13[[#This Row],[Month]]="April",4,IF(All_India_Index_Upto_April23__13[[#This Row],[Month]]="May",5,IF(All_India_Index_Upto_April23__13[[#This Row],[Month]]="June",6,IF(All_India_Index_Upto_April23__13[[#This Row],[Month]]="July",7,IF(All_India_Index_Upto_April23__13[[#This Row],[Month]]="August",8,IF(All_India_Index_Upto_April23__13[[#This Row],[Month]]="September",9,IF(All_India_Index_Upto_April23__13[[#This Row],[Month]]="October",10,IF(All_India_Index_Upto_April23__13[[#This Row],[Month]]="November",11,IF(All_India_Index_Upto_April23__13[[#This Row],[Month]]="December",12))))))))))))) -> 1
A4: Rural+Urban | B4: 2021 | C4: January | D4: =DATE(All_India_Index_Upto_April23__13[[#This Row],[Year]],All_India_Index_Upto_April23__13[[#This Row],[Month Number]],1) -> 44197 | E4: =IF(All_India_Index_Upto_April23__13[[#This Row],[Date]]<DATE(2020, 3, 1),"Pre-COVID","Post-COVID") -> Post-COVID | F4: 144.9 | G4: 190.1 | H4: 175.3 | I4: 154.1 | J4: 150.9 | K4: 149.6 | L4: 194.2 | M4: 160.4 | N4: 114.6 | O4: 164 | P4: 151.8 | Q4: 165.6 | R4: 161 | S4: 186.5 | T4: 155.5 | U4: 146.1 | V4: 154.2 | W4: 157.7 | X4: 147.9 | Y4: 150 | Z4: 159.3 | AA4: 141.9 | AB4: 149.6 | AC4: 159.2 | AD4: 156.8 | AE4: 151.9 | AF4: 157.3 | AG4: =IF(All_India_Index_Upto_April23__13[[#This Row],[Month]] = "January", 1,IF(All_India_Index_Upto_April23__13[[#This Row],[Month]]="February",2,IF(All_India_Index_Upto_April23__13[[#This Row],[Month]]="March",3,IF(All_India_Index_Upto_April23__13[[#This Row],[Month]]="Marcrh",3,IF(All_India_Index_Upto_April23__13[[#This Row],[Month]]="April",4,IF(All_India_Index_Upto_April23__13[[#This Row],[Month]]="May",5,IF(All_India_Index_Upto_April23__13[[#This Row],[Month]]="June",6,IF(All_India_Index_Upto_April23__13[[#This Row],[Month]]="July",7,IF(All_India_Index_Upto_April23__13[[#This Row],[Month]]="August",8,IF(All_India_Index_Upto_April23__13[[#This Row],[Month]]="September",9,IF(All_India_Index_Upto_April23__13[[#This Row],[Month]]="October",10,IF(All_India_Index_Upto_April23__13[[#This Row],[Month]]="November",11,IF(All_India_Index_Upto_April23__13[[#This Row],[Month]]="December",12))))))))))))) -> 1
A5: Rural | B5: 2013 | C5: February | D5: =DATE(All_India_Index_Upto_April23__13[[#This Row],[Year]],All_India_Index_Upto_April23__13[[#This Row],[Month Number]],1) -> 41306 | E5: =IF(All_India_Index_Upto_April23__13[[#This Row],[Date]]<DATE(2020, 3, 1),"Pre-COVID","Post-COVID") -> Pre-COVID | F5: 108.4 | G5: 108.7 | H5: 110.2 | I5: 105.4 | J5: 106.7 | K5: 104 | L5: 102.4 | M5: 105.9 | N5: 105.7 | O5: 103.1 | P5: 105.1 | Q5: 107.7 | R5: 106.3 | S5: 105.6 | T5: 107.1 | U5: 106.3 | V5: 107 | W5: 141 | X5: 106.2 | Y5: 105.2 | Z5: 104.4 | AA5: 103.9 | AB5: 104 | AC5: 104.1 | AD5: 104.6 | AE5: 104.4 | AF5: 105.8 | AG5: =IF(All_India_Index_Upto_April23__13[[#This Row],[Month]] = "January", 1,IF(All_India_Index_Upto_April23__13[[#This Row],[Month]]="February",2,IF(All_India_Index_Upto_April23__13[[#This Row],[Month]]="March",3,IF(All_India_Index_Upto_April23__13[[#This Row],[Month]]="Marcrh",3,IF(All_India_Index_Upto_April23__13[[#This Row],[Month]]="April",4,IF(All_India_Index_Upto_April23__13[[#This Row],[Month]]="May",5,IF(All_India_Index_Upto_April23__13[[#This Row],[Month]]="June",6,IF(All_India_Index_Upto_April23__13[[#This Row],[Month]]="July",7,IF(All_India_Index_Upto_April23__13[[#This Row],[Month]]="August",8,IF(All_India_Index_Upto_April23__13[[#This Row],[Month]]="September",9,IF(All_India_Index_Upto_April23__13[[#This Row],[Month]]="October",10,IF(All_India_Index_Upto_April23__13[[#This Row],[Month]]="November",11,IF(All_India_Index_Upto_April23__13[[#This Row],[Month]]="December",12))))))))))))) -> 2
A6: Urban | B6: 2013 | C6: February | D6: =DATE(All_India_Index_Upto_April23__13[[#This Row],[Year]],All_India_Index_Upto_April23__13[[#This Row],[Month Number]],1) -> 41306 | E6: =IF(All_India_Index_Upto_April23__13[[#This Row],[Date]]<DATE(2020, 3, 1),"Pre-COVID","Post-COVID") -> Pre-COVID | F6: 112.9 | G6: 112.9 | H6: 116.9 | I6: 104 | J6: 103.5 | K6: 103.1 | L6: 104.9 | M6: 104.1 | N6: 103.8 | O6: 102.3 | P6: 106 | Q6: 109 | R6: 107.2 | S6: 106 | T6: 106.6 | U6: 105.5 | V6: 106.4 | W6: 100.4 | X6: 105.7 | Y6: 105.2 | Z6: 104.7 | AA6: 104.4 | AB6: 103.3 | AC6: 103.7 | AD6: 104.3 | AE6: 104.3 | AF6: 104.7 | AG6: =IF(All_India_Index_Upto_April23__13[[#This Row],[Month]] = "January", 1,IF(All_India_Index_Upto_April23__13[[#This Row],[Month]]="February",2,IF(All_India_Index_Upto_April23__13[[#This Row],[Month]]="March",3,IF(All_India_Index_Upto_April23__13[[#This Row],[Month]]="Marcrh",3,IF(All_India_Index_Upto_April23__13[[#This Row],[Month]]="April",4,IF(All_India_Index_Upto_April23__13[[#This Row],[Month]]="May",5,IF(All_India_Index_Upto_April23__13[[#This Row],[Month]]="June",6,IF(All_India_Index_Upto_April23__13[[#This Row],[Month]]="July",7,IF(All_India_Index_Upto_April23__13[[#This Row],[Month]]="August",8,IF(All_India_Index_Upto_April23__13[[#This Row],[Month]]="September",9,IF(All_India_Index_Upto_April23__13[[#This Row],[Month]]="October",10,IF(All_India_Index_Upto_April23__13[[#This Row],[Month]]="November",11,IF(All_India_Index_Upto_April23__13[[#This Row],[Month]]="December",12))))))))))))) -> 2
A7: Rural+Urban | B7: 2021 | C7: February | D7: =DATE(All_India_Index_Upto_April23__13[[#This Row],[Year]],All_India_Index_Upto_April23__13[[#This Row],[Month Number]],1) -> 44228 | E7: =IF(All_India_Index_Upto_April23__13[[#This Row],[Date]]<DATE(2020, 3, 1),"Pre-COVID","Post-COVID") -> Post-COVID | F7: 144.3 | G7: 186.5 | H7: 168.7 | I7: 154.7 | J7: 158.7 | K7: 150.7 | L7: 160 | M7: 158.8 | N7: 112.8 | O7: 164.2 | P7: 155.5 | Q7: 167.5 | R7: 156.9 | S7: 188.3 | T7: 157.2 | U7: 147.4 | V7: 155.8 | W7: 159.8 | X7: 152.4 | Y7: 150.9 | Z7: 161.3 | AA7: 145.1 | AB7: 151.5 | AC7: 159.5 | AD7: 155.8 | AE7: 153.4 | AF7: 156.6 | AG7: =IF(All_India_Index_Upto_April23__13[[#This Row],[Month]] = "January", 1,IF(All_India_Index_Upto_April23__13[[#This Row],[Month]]="February",2,IF(All_India_Index_Upto_April23__13[[#This Row],[Month]]="March",3,IF(All_India_Index_Upto_April23__13[[#This Row],[Month]]="Marcrh",3,IF(All_India_Index_Upto_April23__13[[#This Row],[Month]]="April",4,IF(All_India_Index_Upto_April23__13[[#This Row],[Month]]="May",5,IF(All_India_Index_Upto_April23__13[[#This Row],[Month]]="June",6,IF(All_India_Index_Upto_April23__13[[#This Row],[Month]]="July",7,IF(All_India_Index_Upto_April23__13[[#This Row],[Month]]="August",8,IF(All_India_Index_Upto_April23__13[[#This Row],[Month]]="September",9,IF(All_India_Index_Upto_April23__13[[#This Row],[Month]]="October",10,IF(All_India_Index_Upto_April23__13[[#This Row],[Month]]="November",11,IF(All_India_Index_Upto_April23__13[[#This Row],[Month]]="December",12))))))))))))) -> 2
A8: Rural | B8: 2013 | C8: March | D8: =DATE(All_India_Index_Upto_April23__13[[#This Row],[Year]],All_India_Index_Upto_April23__13[[#This Row],[Month Number]],1) -> 41334 | E8: =IF(All_India_Index_Upto_April23__13[[#This Row],[Date]]<DATE(2020, 3, 1),"Pre-COVID","Post-COVID") -> Pre-COVID | F8: 110.2 | G8: 108.8 | H8: 109.9 | I8: 105.6 | J8: 106.2 | K8: 105.7 | L8: 101.4 | M8: 105.7 | N8: 105 | O8: 103.3 | P8: 105.6 | Q8: 108.2 | R8: 106.6 | S8: 106.5 | T8: 107.6 | U8: 106.8 | V8: 107.5 | W8: 141 | X8: 106.1 | Y8: 105.6 | Z8: 104.7 | AA8: 104.6 | AB8: 104 | AC8: 104.3 | AD8: 104.3 | AE8: 104.6 | AF8: 106 | AG8: =IF(All_India_Index_Upto_April23__13[[#This Row],[Month]] = "January", 1,IF(All_India_Index_Upto_April23__13[[#This Row],[Month]]="February",2,IF(All_India_Index_Upto_April23__13[[#This Row],[Month]]="March",3,IF(All_India_Index_Upto_April23__13[[#This Row],[Month]]="Marcrh",3,IF(All_India_Index_Upto_April23__13[[#This Row],[Month]]="April",4,IF(All_India_Index_Upto_April23__13[[#This Row],[Month]]="May",5,IF(All_India_Index_Upto_April23__13[[#This Row],[Month]]="June",6,IF(All_India_Index_Upto_April23__13[[#This Row],[Month]]="July",7,IF(All_India_Index_Upto_April23__13[[#This Row],[Month]]="August",8,IF(All_India_Index_Upto_April23__13[[#This Row],[Month]]="September",9,IF(All_India_Index_Upto_April23__13[[#This Row],[Month]]="October",10,IF(All_India_Index_Upto_April23__13[[#This Row],[Month]]="November",11,IF(All_India_Index_Upto_April23__13[[#This Row],[Month]]="December",12))))))))))))) -> 3
A9: Urban | B9: 2013 | C9: March | D9: =DATE(All_India_Index_Upto_April23__13[[#This Row],[Year]],All_India_Index_Upto_April23__13[[#This Row],[Month Number]],1) -> 41334 | E9: =IF(All_India_Index_Upto_April23__13[[#This Row],[Date]]<DATE(2020, 3, 1),"Pre-COVID","Post-COVID") -> Pre-COVID | F9: 113.9 | G9: 111.4 | H9: 113.2 | I9: 104.3 | J9: 102.7 | K9: 104.9 | L9: 103.8 | M9: 103.5 | N9: 102.6 | O9: 102.4 | P9: 107 | Q9: 109.8 | R9: 107.3 | S9: 106.8 | T9: 107.2 | U9: 106 | V9: 107 | W9: 100.4 | X9: 106 | Y9: 105.7 | Z9: 105.2 | AA9: 105.5 | AB9: 103.5 | AC9: 103.8 | AD9: 104.2 | AE9: 104.9 | AF9: 105 | AG9: =IF(All_India_Index_Upto_April23__13[[#This Row],[Month]] = "January", 1,IF(All_India_Index_Upto_April23__13[[#This Row],[Month]]="February",2,IF(All_India_Index_Upto_April23__13[[#This Row],[Month]]="March",3,IF(All_India_Index_Upto_April23__13[[#This Row],[Month]]="Marcrh",3,IF(All_India_Index_Upto_April23__13[[#This Row],[Month]]="April",4,IF(All_India_Index_Upto_April23__13[[#This Row],[Month]]="May",5,IF(All_India_Index_Upto_April23__13[[#This Row],[Month]]="June",6,IF(All_India_Index_Upto_April23__13[[#This Row],[Month]]="July",7,IF(All_India_Index_Upto_April23__13[[#This Row],[Month]]="August",8,IF(All_India_Index_Upto_April23__13[[#This Row],[Month]]="September",9,IF(All_India_Index_Upto_April23__13[[#This Row],[Month]]="October",10,IF(All_India_Index_Upto_April23__13[[#This Row],[Month]]="November",11,IF(All_India_Index_Upto_April23__13[[#This Row],[Month]]="December",12))))))))))))) -> 3
A10: Rural+Urban | B10: 2021 | C10: March | D10: =DATE(All_India_Index_Upto_April23__13[[#This Row],[Year]],All_India_Index_Upto_April23__13[[#This Row],[Month Number]],1) -> 44256 | E10: =IF(All_India_Index_Upto_April23__13[[#This Row],[Date]]<DATE(2020, 3, 1),"Pre-COVID","Post-COVID") -> Post-COVID | F10: 144.1 | G10: 192.2 | H10: 163.8 | I10: 154.9 | J10: 163.9 | K10: 153.7 | L10: 149.5 | M10: 159.8 | N10: 112.6 | O10: 163.5 | P10: 156.5 | Q10: 168.2 | R10: 156.7 | S10: 188.1 | T10: 157.8 | U10: 147.9 | V10: 156.4 | W10: 159.9 | X10: 155.5 | Y10: 151.2 | Z10: 161.7 | AA10: 146.2 | AB10: 152.6 | AC10: 160.2 | AD10: 153.8 | AE10: 153.8 | AF10: 156.8 | AG10: =IF(All_India_Index_Upto_April23__13[[#This Row],[Month]] = "January", 1,IF(All_India_Index_Upto_April23__13[[#This Row],[Month]]="February",2,IF(All_India_Index_Upto_April23__13[[#This Row],[Month]]="March",3,IF(All_India_Index_Upto_April23__13[[#This Row],[Month]]="Marcrh",3,IF(All_India_Index_Upto_April23__13[[#This Row],[Month]]="April",4,IF(All_India_Index_Upto_April23__13[[#This Row],[Month]]="May",5,IF(All_India_Index_Upto_April23__13[[#This Row],[Month]]="June",6,IF(All_India_Index_Upto_April23__13[[#This Row],[Month]]="July",7,IF(All_India_Index_Upto_April23__13[[#This Row],[Month]]="August",8,IF(All_India_Index_Upto_April23__13[[#This Row],[Month]]="September",9,IF(All_India_Index_Upto_April23__13[[#This Row],[Month]]="October",10,IF(All_India_Index_Upto_April23__13[[#This Row],[Month]]="November",11,IF(All_India_Index_Upto_April23__13[[#This Row],[Month]]="December",12))))))))))))) -> 3
A11: Rural | B11: 2013 | C11: April | D11: =DATE(All_India_Index_Upto_April23__13[[#This Row],[Year]],All_India_Index_Upto_April23__13[[#This Row],[Month Number]],1) -> 41365 | E11: =IF(All_India_Index_Upto_April23__13[[#This Row],[Date]]<DATE(2020, 3, 1),"Pre-COVID","Post-COVID") -> Pre-COVID | F11: 110.2 | G11: 109.5 | H11: 106.9 | I11: 106.3 | J11: 105.7 | K11: 108.3 | L11: 103.4 | M11: 105.7 | N11: 104.2 | O11: 103.2 | P11: 106.5 | Q11: 108.8 | R11: 107.1 | S11: 107.1 | T11: 108.1 | U11: 107.4 | V11: 108 | W11: 141 | X11: 106.5 | Y11: 106.1 | Z11: 105.1 | AA11: 104.4 | AB11: 104.5 | AC11: 104.8 | AD11: 102.7 | AE11: 104.6 | AF11: 106.4 | AG11: =IF(All_India_Index_Upto_April23__13[[#This Row],[Month]] = "January", 1,IF(All_India_Index_Upto_April23__13[[#This Row],[Month]]="February",2,IF(All_India_Index_Upto_April23__13[[#This Row],[Month]]="March",3,IF(All_India_Index_Upto_April23__13[[#This Row],[Month]]="Marcrh",3,IF(All_India_Index_Upto_April23__13[[#This Row],[Month]]="April",4,IF(All_India_Index_Upto_April23__13[[#This Row],[Month]]="May",5,IF(All_India_Index_Upto_April23__13[[#This Row],[Month]]="June",6,IF(All_India_Index_Upto_April23__13[[#This Row],[Month]]="July",7,IF(All_India_Index_Upto_April23__13[[#This Row],[Month]]="August",8,IF(All_India_Index_Upto_April23__13[[#This Row],[Month]]="September",9,IF(All_India_Index_Upto_April23__13[[#This Row],[Month]]="October",10,IF(All_India_Index_Upto_April23__13[[#This Row],[Month]]="November",11,IF(All_India_Index_Upto_April23__13[[#This Row],[Month]]="December",12))))))))))))) -> 4
A12: Urban | B12: 2013 | C12: April | D12: =DATE(All_India_Index_Upto_April23__13[[#This Row],[Year]],All_India_Index_Upto_April23__13[[#This Row],[Month Number]],1) -> 41365 | E12: =IF(All_India_Index_Upto_April23__13[[#This Row],[Date]]<DATE(2020, 3, 1),"Pre-COVID","Post-COVID") -> Pre-COVID | F12: 114.6 | G12: 113.4 | H12: 106 | I12: 104.7 | J12: 102.1 | K12: 109.5 | L12: 109.7 | M12: 104.6 | N12: 102 | O12: 103.5 | P12: 108.2 | Q12: 110.6 | R12: 108.8 | S12: 108.5 | T12: 107.9 | U12: 106.4 | V12: 107.7 | W12: 100.5 | X12: 106.4 | Y12: 106.5 | Z12: 105.7 | AA12: 105 | AB12: 104 | AC12: 105.2 | AD12: 103.2 | AE12: 105.1 | AF12: 105.7 | AG12: =IF(All_India_Index_Upto_April23__13[[#This Row],[Month]] = "January", 1,IF(All_India_Index_Upto_April23__13[[#This Row],[Month]]="February",2,IF(All_India_Index_Upto_April23__13[[#This Row],[Month]]="March",3,IF(All_India_Index_Upto_April23__13[[#This Row],[Month]]="Marcrh",3,IF(All_India_Index_Upto_April23__13[[#This Row],[Month]]="April",4,IF(All_India_Index_Upto_April23__13[[#This Row],[Month]]="May",5,IF(All_India_Index_Upto_April23__13[[#This Row],[Month]]="June",6,IF(All_India_Index_Upto_April23__13[[#This Row],[Month]]="July",7,IF(All_India_Index_Upto_April23__13[[#This Row],[Month]]="August",8,IF(All_India_Index_Upto_April23__13[[#This Row],[Month]]="September",9,IF(All_India_Index_Upto_April23__13[[#This Row],[Month]]="October",10,IF(All_India_Index_Upto_April23__13[[#This Row],[Month]]="November",11,IF(All_India_Index_Upto_April23__13[[#This Row],[Month]]="December",12))))))))))))) -> 4
A13: Rural+Urban | B13: 2021 | C13: April | D13: =DATE(All_India_Index_Upto_April23__13[[#This Row],[Year]],All_India_Index_Upto_April23__13[[#This Row],[Month Number]],1) -> 44287 | E13: =IF(All_India_Index_Upto_April23__13[[#This Row],[Date]]<DATE(2020, 3, 1),"Pre-COVID","Post-COVID") -> Post-COVID | F13: 144.3 | G13: 198 | H13: 164.6 | I13: 155.4 | J13: 170.1 | K13: 164.4 | L13: 144.1 | M13: 161.7 | N13: 113.1 | O13: 163.9 | P13: 157.6 | Q13: 168.9 | R13: 158 | S13: 188.8 | T13: 158.8 | U13: 148.5 | V13: 157.3 | W13: 161.4 | X13: 155.6 | Y13: 151.8 | Z13: 162.3 | AA13: 146.6 | AB13: 153.2 | AC13: 160.3 | AD13: 155.4 | AE13: 154.4 | AF13: 157.8 | AG13: =IF(All_India_Index_Upto_April23__13[[#This Row],[Month]] = "January", 1,IF(All_India_Index_Upto_April23__13[[#This Row],[Month]]="February",2,IF(All_India_Index_Upto_April23__13[[#This Row],[Month]]="March",3,IF(All_India_Index_Upto_April23__13[[#This Row],[Month]]="Marcrh",3,IF(All_India_Index_Upto_April23__13[[#This Row],[Month]]="April",4,IF(All_India_Index_Upto_April23__13[[#This Row],[Month]]="May",5,IF(All_India_Index_Upto_April23__13[[#This Row],[Month]]="June",6,IF(All_India_Index_Upto_April23__13[[#This Row],[Month]]="July",7,IF(All_India_Index_Upto_April23__13[[#This Row],[Month]]="August",8,IF(All_India_Index_Upto_April23__13[[#This Row],[Month]]="September",9,IF(All_India_Index_Upto_April23__13[[#This Row],[Month]]="October",10,IF(All_India_Index_Upto_April23__13[[#This Row],[Month]]="November",11,IF(All_India_Index_Upto_April23__13[[#This Row],[Month]]="December",12))))))))))))) -> 4
... A111: Urban | B111: 2016 | C111: January | D111: =DATE(All_India_Index_Upto_April23__13[[#This Row],[Year]],All_India_Index_Upto_April23__13[[#This Row],[Month Number]],1) -> 42370 | E111: =IF(All_India_Index_Upto_April23__13[[#This Row],[Date]]<DATE(2020, 3, 1),"Pre-COVID","Post-COVID") -> Pre-COVID | F111: 124.7 | G111: 135.9 | H111: 132 | I111: 129.2 | J111: 109.7 | K111: 119 | L111: 144.1 | M111: 184.2 | N111: 96.7 | O111: 139.5 | P111: 120.5 | Q111: 134.7 | R111: 131.2 | S111: 139.5 | T111: 125.8 | U111: 119.8 | V111: 124.9 | W111: 123.4 | X111: 116.9 | Y111: 121.6 | Z111: 119.1 | AA111: 108.9 | AB111: 118.5 | AC111: 126.4 | AD111: 114 | AE111: 116.8 | AF111: 124.2 | AG111: =IF(All_India_Index_Upto_April23__13[[#This Row],[Month]] = "January", 1,IF(All_India_Index_Upto_April23__13[[#This Row],[Month]]="February",2,IF(All_India_Index_Upto_April23__13[[#This Row],[Month]]="March",3,IF(All_India_Index_Upto_April23__13[[#This Row],[Month]]="Marcrh",3,IF(All_India_Index_Upto_April23__13[[#This Row],[Month]]="April",4,IF(All_India_Index_Upto_April23__13[[#This Row],[Month]]="May",5,IF(All_India_Index_Upto_April23__13[[#This Row],[Month]]="June",6,IF(All_India_Index_Upto_April23__13[[#This Row],[Month]]="July",7,IF(All_India_Index_Upto_April23__13[[#This Row],[Month]]="August",8,IF(All_India_Index_Upto_April23__13[[#This Row],[Month]]="September",9,IF(All_India_Index_Upto_April23__13[[#This Row],[Month]]="October",10,IF(All_India_Index_Upto_April23__13[[#This Row],[Month]]="November",11,IF(All_India_Index_Upto_April23__13[[#This Row],[Month]]="December",12))))))))))))) -> 1
A112: Rural+Urban | B112: 2020 | C112: May | D112: =DATE(All_India_Index_Upto_April23__13[[#This Row],[Year]],All_India_Index_Upto_April23__13[[#This Row],[Month Number]],1) -> 43952 | E112: =IF(All_India_Index_Upto_April23__13[[#This Row],[Date]]<DATE(2020, 3, 1),"Pre-COVID","Post-COVID") -> Post-COVID | F112: =VALUE('Missing Values Handled'!$G$8) -> 135.9 | G112: ='Missing Values Handled'!$H$8 -> 144.2 | H112: ='Missing Values Handled'!$I$8 -> 135.5 | I112: ='Missing Values Handled'!J$8 -> 144.2 | J112: ='Missing Values Handled'!K$8 -> 135.5 | K112: ='Missing Values Handled'!L$8 -> 141 | L112: ='Missing Values Handled'!M$8 -> 135.5 | M112: ='Missing Values Handled'!N$8 -> 141 | N112: ='Missing Values Handled'!O$8 -> 120.5 | O112: ='Missing Values Handled'!P$8 -> 141 | P112: ='Missing Values Handled'!Q$8 -> 144.2 | ... V112: ='Missing Values Handled'!W$8 -> 135.5 | W112: 141 | X112: ='Missing Values Handled'!Y$8 -> 120.5 | Y112: ='Missing Values Handled'!Z$8 -> 144.2 | Z112: ='Missing Values Handled'!AA$8 -> 135.5 | AA112: ='Missing Values Handled'!AB$8 -> 141 | AB112: ='Missing Values Handled'!AC$8 -> 135.5 | AC112: ='Missing Values Handled'!AD$8 -> 141 | AD112: ='Missing Values Handled'!AE$8 -> 144.2 | AE112: ='Missing Values Handled'!AF$8 -> 135.5 | AF112: ='Missing Values Handled'!AG$8 -> 141 | AG112: =IF(All_India_Index_Upto_April23__13[[#This Row],[Month]] = "January", 1,IF(All_India_Index_Upto_April23__13[[#This Row],[Month]]="February",2,IF(All_India_Index_Upto_April23__13[[#This Row],[Month]]="March",3,IF(All_India_Index_Upto_April23__13[[#This Row],[Month]]="Marcrh",3,IF(All_India_Index_Upto_April23__13[[#This Row],[Month]]="April",4,IF(All_India_Index_Upto_April23__13[[#This Row],[Month]]="May",5,IF(All_India_Index_Upto_April23__13[[#This Row],[Month]]="June",6,IF(All_India_Index_Upto_April23__13[[#This Row],[Month]]="July",7,IF(All_India_Index_Upto_April23__13[[#This Row],[Month]]="August",8,IF(All_India_Index_Upto_April23__13[[#This Row],[Month]]="September",9,IF(All_India_Index_Upto_April23__13[[#This Row],[Month]]="October",10,IF(All_India_Index_Upto_April23__13[[#This Row],[Month]]="November",11,IF(All_India_Index_Upto_April23__13[[#This Row],[Month]]="December",12))))))))))))) -> 5
A113: Rural | B113: 2016 | C113: February | D113: =DATE(All_India_Index_Upto_April23__13[[#This Row],[Year]],All_India_Index_Upto_April23__13[[#This Row],[Month Number]],1) -> 42401 | E113: =IF(All_India_Index_Upto_April23__13[[#This Row],[Date]]<DATE(2020, 3, 1),"Pre-COVID","Post-COVID") -> Pre-COVID | F113: 127.1 | G113: 133.7 | H113: 127.7 | I113: 130.7 | J113: 118.5 | K113: 130.4 | L113: 130.9 | M113: 162.8 | N113: 98.7 | O113: 130.6 | P113: 124.8 | Q113: 136.4 | R113: 130.3 | S113: 134.4 | T113: 133.9 | U113: 129.8 | V113: 133.4 | W113: 141 | X113: 127.5 | Y113: 127.1 | Z113: 124.3 | AA113: 113.9 | AB113: 122.3 | AC113: 127.1 | AD113: 116.8 | AE113: 120.9 | AF113: 127.9 | AG113: =IF(All_India_Index_Upto_April23__13[[#This Row],[Month]] = "January", 1,IF(All_India_Index_Upto_April23__13[[#This Row],[Month]]="February",2,IF(All_India_Index_Upto_April23__13[[#This Row],[Month]]="March",3,IF(All_India_Index_Upto_April23__13[[#This Row],[Month]]="Marcrh",3,IF(All_India_Index_Upto_April23__13[[#This Row],[Month]]="April",4,IF(All_India_Index_Upto_April23__13[[#This Row],[Month]]="May",5,IF(All_India_Index_Upto_April23__13[[#This Row],[Month]]="June",6,IF(All_India_Index_Upto_April23__13[[#This Row],[Month]]="July",7,IF(All_India_Index_Upto_April23__13[[#This Row],[Month]]="August",8,IF(All_India_Index_Upto_April23__13[[#This Row],[Month]]="September",9,IF(All_India_Index_Upto_April23__13[[#This Row],[Month]]="October",10,IF(All_India_Index_Upto_April23__13[[#This Row],[Month]]="November",11,IF(All_India_Index_Upto_April23__13[[#This Row],[Month]]="December",12))))))))))))) -> 2
A114: Urban | B114: 2016 | C114: February | D114: =DATE(All_India_Index_Upto_April23__13[[#This Row],[Year]],All_India_Index_Upto_April23__13[[#This Row],[Month Number]],1) -> 42401 | E114: =IF(All_India_Index_Upto_April23__13[[#This Row],[Date]]<DATE(2020, 3, 1),"Pre-COVID","Post-COVID") -> Pre-COVID | F114: 124.8 | G114: 135.1 | H114: 130.3 | I114: 129.6 | J114: 108.4 | K114: 118.6 | L114: 129.2 | M114: 176.4 | N114: 99.1 | O114: 139.7 | P114: 120.6 | Q114: 135.2 | R114: 129.1 | S114: 140 | T114: 126.2 | U114: 120.1 | V114: 125.3 | W114: 124.4 | X114: 116 | Y114: 121.8 | Z114: 119.5 | AA114: 109.1 | AB114: 118.8 | AC114: 126.3 | AD114: 116.2 | AE114: 117.2 | AF114: 123.8 | AG114: =IF(All_India_Index_Upto_April23__13[[#This Row],[Month]] = "January", 1,IF(All_India_Index_Upto_April23__13[[#This Row],[Month]]="February",2,IF(All_India_Index_Upto_April23__13[[#This Row],[Month]]="March",3,IF(All_India_Index_Upto_April23__13[[#This Row],[Month]]="Marcrh",3,IF(All_India_Index_Upto_April23__13[[#This Row],[Month]]="April",4,IF(All_India_Index_Upto_April23__13[[#This Row],[Month]]="May",5,IF(All_India_Index_Upto_April23__13[[#This Row],[Month]]="June",6,IF(All_India_Index_Upto_April23__13[[#This Row],[Month]]="July",7,IF(All_India_Index_Upto_April23__13[[#This Row],[Month]]="August",8,IF(All_India_Index_Upto_April23__13[[#This Row],[Month]]="September",9,IF(All_India_Index_Upto_April23__13[[#This Row],[Month]]="October",10,IF(All_India_Index_Upto_April23__13[[#This Row],[Month]]="November",11,IF(All_India_Index_Upto_April23__13[[#This Row],[Month]]="December",12))))))))))))) -> 2
A115: Rural+Urban | B115: 2020 | C115: April | D115: =DATE(All_India_Index_Upto_April23__13[[#This Row],[Year]],All_India_Index_Upto_April23__13[[#This Row],[Month Number]],1) -> 43922 | E115: =IF(All_India_Index_Upto_April23__13[[#This Row],[Date]]<DATE(2020, 3, 1),"Pre-COVID","Post-COVID") -> Post-COVID | F115: 148.7 | G115: ='Missing Values Handled'!$H$8 -> 144.2 | H115: 148.8 | I115: 155.6 | J115: 135.1 | K115: 149.9 | L115: 168.6 | M115: 150.4 | N115: 120.3 | O115: 157.1 | P115: 136.8 | Q115: ='Missing Values Handled'!R$8 -> 135.5 | R115: 151.4 | S115: ='Missing Values Handled'!T$8 -> 144.2 | T115: ='Missing Values Handled'!U$8 -> 135.5 | U115: ='Missing Values Handled'!V$8 -> 141 | V115: ='Missing Values Handled'!W$8 -> 135.5 | W115: 155.6 | X115: 144.1 | Y115: ='Missing Values Handled'!Z$8 -> 144.2 | Z115: 150.7 | AA115: ='Missing Values Handled'!AB$8 -> 141 | AB115: ='Missing Values Handled'!AC$8 -> 135.5 | AC115: ='Missing Values Handled'!AD$8 -> 141 | AD115: ='Missing Values Handled'!AE$8 -> 144.2 | AE115: ='Missing Values Handled'!AF$8 -> 135.5 | AF115: ='Missing Values Handled'!AG$8 -> 141 | AG115: =IF(All_India_Index_Upto_April23__13[[#This Row],[Month]] = "January", 1,IF(All_India_Index_Upto_April23__13[[#This Row],[Month]]="February",2,IF(All_India_Index_Upto_April23__13[[#This Row],[Month]]="March",3,IF(All_India_Index_Upto_April23__13[[#This Row],[Month]]="Marcrh",3,IF(All_India_Index_Upto_April23__13[[#This Row],[Month]]="April",4,IF(All_India_Index_Upto_April23__13[[#This Row],[Month]]="May",5,IF(All_India_Index_Upto_April23__13[[#This Row],[Month]]="June",6,IF(All_India_Index_Upto_April23__13[[#This Row],[Month]]="July",7,IF(All_India_Index_Upto_April23__13[[#This Row],[Month]]="August",8,IF(All_India_Index_Upto_April23__13[[#This Row],[Month]]="September",9,IF(All_India_Index_Upto_April23__13[[#This Row],[Month]]="October",10,IF(All_India_Index_Upto_April23__13[[#This Row],[Month]]="November",11,IF(All_India_Index_Upto_April23__13[[#This Row],[Month]]="December",12))))))))))))) -> 4
A116: Rural | B116: 2016 | C116: March | D116: =DATE(All_India_Index_Upto_April23__13[[#This Row],[Year]],All_India_Index_Upto_April23__13[[#This Row],[Month Number]],1) -> 42430 | E116: =IF(All_India_Index_Upto_April23__13[[#This Row],[Date]]<DATE(2020, 3, 1),"Pre-COVID","Post-COVID") -> Pre-COVID | F116: 127.3 | G116: 134.4 | H116: 125.1 | I116: 130.5 | J116: 118.3 | K116: 131.7 | L116: 130.7 | M116: 161.2 | N116: 100.4 | O116: 130.8 | P116: 124.9 | Q116: 137 | R116: 130.4 | S116: 135 | T116: 134.4 | U116: 130.2 | V116: 133.8 | W116: 141 | X116: 127 | Y116: 127.7 | Z116: 124.8 | AA116: 113.6 | AB116: 122.5 | AC116: 127.5 | AD116: 117.4 | AE116: 121.1 | AF116: 128 | AG116: =IF(All_India_Index_Upto_April23__13[[#This Row],[Month]] = "January", 1,IF(All_India_Index_Upto_April23__13[[#This Row],[Month]]="February",2,IF(All_India_Index_Upto_April23__13[[#This Row],[Month]]="March",3,IF(All_India_Index_Upto_April23__13[[#This Row],[Month]]="Marcrh",3,IF(All_India_Index_Upto_April23__13[[#This Row],[Month]]="April",4,IF(All_India_Index_Upto_April23__13[[#This Row],[Month]]="May",5,IF(All_India_Index_Upto_April23__13[[#This Row],[Month]]="June",6,IF(All_India_Index_Upto_April23__13[[#This Row],[Month]]="July",7,IF(All_India_Index_Upto_April23__13[[#This Row],[Month]]="August",8,IF(All_India_Index_Upto_April23__13[[#This Row],[Month]]="September",9,IF(All_India_Index_Upto_April23__13[[#This Row],[Month]]="October",10,IF(All_India_Index_Upto_April23__13[[#This Row],[Month]]="November",11,IF(All_India_Index_Upto_April23__13[[#This Row],[Month]]="December",12))))))))))))) -> 3
A117: Urban | B117: 2016 | C117: March | D117: =DATE(All_India_Index_Upto_April23__13[[#This Row],[Year]],All_India_Index_Upto_April23__13[[#This Row],[Month Number]],1) -> 42430 | E117: =IF(All_India_Index_Upto_April23__13[[#This Row],[Date]]<DATE(2020, 3, 1),"Pre-COVID","Post-COVID") -> Pre-COVID | F117: 124.8 | G117: 136.3 | H117: 123.7 | I117: 129.7 | J117: 107.9 | K117: 119.9 | L117: 128.1 | M117: 170.3 | N117: 101.8 | O117: 140.1 | P117: 120.7 | Q117: 135.4 | R117: 128.9 | S117: 140.6 | T117: 126.4 | U117: 120.3 | V117: 125.5 | W117: 124.9 | X117: 114.8 | Y117: 122.3 | Z117: 119.7 | AA117: 108.5 | AB117: 119.1 | AC117: 126.4 | AD117: 117.1 | AE117: 117.3 | AF117: 123.8 | AG117: =IF(All_India_Index_Upto_April23__13[[#This Row],[Month]] = "January", 1,IF(All_India_Index_Upto_April23__13[[#This Row],[Month]]="February",2,IF(All_India_Index_Upto_April23__13[[#This Row],[Month]]="March",3,IF(All_India_Index_Upto_April23__13[[#This Row],[Month]]="Marcrh",3,IF(All_India_Index_Upto_April23__13[[#This Row],[Month]]="April",4,IF(All_India_Index_Upto_April23__13[[#This Row],[Month]]="May",5,IF(All_India_Index_Upto_April23__13[[#This Row],[Month]]="June",6,IF(All_India_Index_Upto_April23__13[[#This Row],[Month]]="July",7,IF(All_India_Index_Upto_April23__13[[#This Row],[Month]]="August",8,IF(All_India_Index_Upto_April23__13[[#This Row],[Month]]="September",9,IF(All_India_Index_Upto_April23__13[[#This Row],[Month]]="October",10,IF(All_India_Index_Upto_April23__13[[#This Row],[Month]]="November",11,IF(All_India_Index_Upto_April23__13[[#This Row],[Month]]="December",12))))))))))))) -> 3
A118: Rural+Urban | B118: 2020 | C118: March | D118: =DATE(All_India_Index_Upto_April23__13[[#This Row],[Year]],All_India_Index_Upto_April23__13[[#This Row],[Month Number]],1) -> 43891 | E118: =IF(All_India_Index_Upto_April23__13[[#This Row],[Date]]<DATE(2020, 3, 1),"Pre-COVID","Post-COVID") -> Post-COVID | F118: 145.1 | G118: 167 | H118: 148.1 | I118: 151.5 | J118: 131.2 | K118: 142.5 | L118: 157.3 | M118: 141.1 | N118: 113.2 | O118: 153.2 | P118: 136.7 | Q118: 159.6 | R118: 148.9 | S118: 171.2 | T118: 151.2 | U118: 141.9 | V118: 149.8 | W118: 154.5 | X118: 148.9 | Y118: 146.4 | Z118: 152.3 | AA118: 129.9 | AB118: 143.7 | AC118: 156.1 | AD118: 145.2 | AE118: 143.8 | AF118: 148.6 | AG118: =IF(All_India_Index_Upto_April23__13[[#This Row],[Month]] = "January", 1,IF(All_India_Index_Upto_April23__13[[#This Row],[Month]]="February",2,IF(All_India_Index_Upto_April23__13[[#This Row],[Month]]="March",3,IF(All_India_Index_Upto_April23__13[[#This Row],[Month]]="Marcrh",3,IF(All_India_Index_Upto_April23__13[[#This Row],[Month]]="April",4,IF(All_India_Index_Upto_April23__13[[#This Row],[Month]]="May",5,IF(All_India_Index_Upto_April23__13[[#This Row],[Month]]="June",6,IF(All_India_Index_Upto_April23__13[[#This Row],[Month]]="July",7,IF(All_India_Index_Upto_April23__13[[#This Row],[Month]]="August",8,IF(All_India_Index_Upto_April23__13[[#This Row],[Month]]="September",9,IF(All_India_Index_Upto_April23__13[[#This Row],[Month]]="October",10,IF(All_India_Index_Upto_April23__13[[#This Row],[Month]]="November",11,IF(All_India_Index_Upto_April23__13[[#This Row],[Month]]="December",12))))))))))))) -> 3
A119: Rural | B119: 2016 | C119: April | D119: =DATE(All_India_Index_Upto_April23__13[[#This Row],[Year]],All_India_Index_Upto_April23__13[[#This Row],[Month Number]],1) -> 42461 | E119: =IF(All_India_Index_Upto_April23__13[[#This Row],[Date]]<DATE(2020, 3, 1),"Pre-COVID","Post-COVID") -> Pre-COVID | F119: 127.4 | G119: 135.4 | H119: 123.4 | I119: 131.3 | J119: 118.2 | K119: 138.1 | L119: 134.1 | M119: 162.7 | N119: 105 | O119: 131.4 | P119: 125.4 | Q119: 137.4 | R119: 131.8 | S119: 135.5 | T119: 135 | U119: 130.6 | V119: 134.4 | W119: 141 | X119: 127 | Y119: 128 | Z119: 125.2 | AA119: 114.4 | AB119: 123.2 | AC119: 127.9 | AD119: 118.4 | AE119: 121.7 | AF119: 129 | AG119: =IF(All_India_Index_Upto_April23__13[[#This Row],[Month]] = "January", 1,IF(All_India_Index_Upto_April23__13[[#This Row],[Month]]="February",2,IF(All_India_Index_Upto_April23__13[[#This Row],[Month]]="March",3,IF(All_India_Index_Upto_April23__13[[#This Row],[Month]]="Marcrh",3,IF(All_India_Index_Upto_April23__13[[#This Row],[Month]]="April",4,IF(All_India_Index_Upto_April23__13[[#This Row],[Month]]="May",5,IF(All_India_Index_Upto_April23__13[[#This Row],[Month]]="June",6,IF(All_India_Index_Upto_April23__13[[#This Row],[Month]]="July",7,IF(All_India_Index_Upto_April23__13[[#This Row],[Month]]="August",8,IF(All_India_Index_Upto_April23__13[[#This Row],[Month]]="September",9,IF(All_India_Index_Upto_April23__13[[#This Row],[Month]]="October",10,IF(All_India_Index_Upto_April23__13[[#This Row],[Month]]="November",11,IF(All_India_Index_Upto_April23__13[[#This Row],[Month]]="December",12))))))))))))) -> 4
A120: Urban | B120: 2016 | C120: April | D120: =DATE(All_India_Index_Upto_April23__13[[#This Row],[Year]],All_India_Index_Upto_April23__13[[#This Row],[Month Number]],1) -> 42461 | E120: =IF(All_India_Index_Upto_April23__13[[#This Row],[Date]]<DATE(2020, 3, 1),"Pre-COVID","Post-COVID") -> Pre-COVID | F120: 124.9 | G120: 139.3 | H120: 119.9 | I120: 130.2 | J120: 108.9 | K120: 131.1 | L120: 136.8 | M120: 176.9 | N120: 109.1 | O120: 140.4 | P120: 121.1 | Q120: 135.9 | R120: 131.8 | S120: 141.5 | T120: 126.8 | U120: 120.5 | V120: 125.8 | W120: 125.6 | X120: 114.6 | Y120: 122.8 | Z120: 120 | AA120: 110 | AB120: 119.5 | AC120: 127.6 | AD120: 117.6 | AE120: 118.2 | AF120: 125.3 | AG120: =IF(All_India_Index_Upto_April23__13[[#This Row],[Month]] = "January", 1,IF(All_India_Index_Upto_April23__13[[#This Row],[Month]]="February",2,IF(All_India_Index_Upto_April23__13[[#This Row],[Month]]="March",3,IF(All_India_Index_Upto_April23__13[[#This Row],[Month]]="Marcrh",3,IF(All_India_Index_Upto_April23__13[[#This Row],[Month]]="April",4,IF(All_India_Index_Upto_April23__13[[#This Row],[Month]]="May",5,IF(All_India_Index_Upto_April23__13[[#This Row],[Month]]="June",6,IF(All_India_Index_Upto_April23__13[[#This Row],[Month]]="July",7,IF(All_India_Index_Upto_April23__13[[#This Row],[Month]]="August",8,IF(All_India_Index_Upto_April23__13[[#This Row],[Month]]="September",9,IF(All_India_Index_Upto_April23__13[[#This Row],[Month]]="October",10,IF(All_India_Index_Upto_April23__13[[#This Row],[Month]]="November",11,IF(All_India_Index_Upto_April23__13[[#This Row],[Month]]="December",12))))))))))))) -> 4
A121: Rural+Urban | B121: 2020 | C121: February | D121: =DATE(All_India_Index_Upto_April23__13[[#This Row],[Year]],All_India_Index_Upto_April23__13[[#This Row],[Month Number]],1) -> 43862 | E121: =IF(All_India_Index_Upto_April23__13[[#This Row],[Date]]<DATE(2020, 3, 1),"Pre-COVID","Post-COVID") -> Pre-COVID | F121: 144.8 | G121: 167.5 | H121: 151.8 | I121: 150.8 | J121: 131.4 | K121: 141.8 | L121: 170.7 | M121: 141.1 | N121: 113.6 | O121: 152 | P121: 136.5 | Q121: 159.1 | R121: 150.5 | S121: 170.1 | T121: 150.8 | U121: 141.7 | V121: 149.5 | W121: 154.8 | X121: 147.2 | Y121: 146.4 | Z121: 151.7 | AA121: 130.3 | AB121: 143.2 | AC121: 156.2 | AD121: 143.4 | AE121: 143.6 | AF121: 149.1 | AG121: =IF(All_India_Index_Upto_April23__13[[#This Row],[Month]] = "January", 1,IF(All_India_Index_Upto_April23__13[[#This Row],[Month]]="February",2,IF(All_India_Index_Upto_April23__13[[#This Row],[Month]]="March",3,IF(All_India_Index_Upto_April23__13[[#This Row],[Month]]="Marcrh",3,IF(All_India_Index_Upto_April23__13[[#This Row],[Month]]="April",4,IF(All_India_Index_Upto_April23__13[[#This Row],[Month]]="May",5,IF(All_India_Index_Upto_April23__13[[#This Row],[Month]]="June",6,IF(All_India_Index_Upto_April23__13[[#This Row],[Month]]="July",7,IF(All_India_Index_Upto_April23__13[[#This Row],[Month]]="August",8,IF(All_India_Index_Upto_April23__13[[#This Row],[Month]]="September",9,IF(All_India_Index_Upto_April23__13[[#This Row],[Month]]="October",10,IF(All_India_Index_Upto_April23__13[[#This Row],[Month]]="November",11,IF(All_India_Index_Upto_April23__13[[#This Row],[Month]]="December",12))))))))))))) -> 2
A122: Rural | B122: 2016 | C122: May | D122: =DATE(All_India_Index_Upto_April23__13[[#This Row],[Year]],All_India_Index_Upto_April23__13[[#This Row],[Month Number]],1) -> 42491 | E122: =IF(All_India_Index_Upto_April23__13[[#This Row],[Date]]<DATE(2020, 3, 1),"Pre-COVID","Post-COVID") -> Pre-COVID | F122: 127.6 | G122: 137.5 | H122: 124.4 | I122: 132.4 | J122: 118.2 | K122: 138.1 | L122: 141.8 | M122: 166 | N122: 107.5 | O122: 132.2 | P122: 126.1 | Q122: 138.3 | R122: 133.6 | S122: 136 | T122: 135.4 | U122: 131.1 | V122: 134.8 | W122: 141 | X122: 127.4 | Y122: 128.5 | Z122: 125.8 | AA122: 115.1 | AB122: 123.6 | AC122: 129.1 | AD122: 119.7 | AE122: 122.5 | AF122: 130.3 | AG122: =IF(All_India_Index_Upto_April23__13[[#This Row],[Month]] = "January", 1,IF(All_India_Index_Upto_April23__13[[#This Row],[Month]]="February",2,IF(All_India_Index_Upto_April23__13[[#This Row],[Month]]="March",3,IF(All_India_Index_Upto_April23__13[[#This Row],[Month]]="Marcrh",3,IF(All_India_Index_Upto_April23__13[[#This Row],[Month]]="April",4,IF(All_India_Index_Upto_April23__13[[#This Row],[Month]]="May",5,IF(All_India_Index_Upto_April23__13[[#This Row],[Month]]="June",6,IF(All_India_Index_Upto_April23__13[[#This Row],[Month]]="July",7,IF(All_India_Index_Upto_April23__13[[#This Row],[Month]]="August",8,IF(All_India_Index_Upto_April23__13[[#This Row],[Month]]="September",9,IF(All_India_Index_Upto_April23__13[[#This Row],[Month]]="October",10,IF(All_India_Index_Upto_April23__13[[#This Row],[Month]]="November",11,IF(All_India_Index_Upto_April23__13[[#This Row],[Month]]="December",12))))))))))))) -> 5
A123: Urban | B123: 2016 | C123: May | D123: =DATE(All_India_Index_Upto_April23__13[[#This Row],[Year]],All_India_Index_Upto_April23__13[[#This Row],[Month Number]],1) -> 42491 | E123: =IF(All_India_Index_Upto_April23__13[[#This Row],[Date]]<DATE(2020, 3, 1),"Pre-COVID","Post-COVID") -> Pre-COVID | F123: 125 | G123: 142.1 | H123: 127 | I123: 130.4 | J123: 109.6 | K123: 133.5 | L123: 151.4 | M123: 182.8 | N123: 111.1 | O123: 141.5 | P123: 121.5 | Q123: 136.3 | R123: 134.6 | S123: 142.2 | T123: 127.2 | U123: 120.7 | V123: 126.2 | W123: 126 | X123: 115 | Y123: 123.2 | Z123: 120.3 | AA123: 110.7 | AB123: 119.8 | AC123: 128 | AD123: 118.5 | AE123: 118.7 | AF123: 126.6 | AG123: =IF(All_India_Index_Upto_April23__13[[#This Row],[Month]] = "January", 1,IF(All_India_Index_Upto_April23__13[[#This Row],[Month]]="February",2,IF(All_India_Index_Upto_April23__13[[#This Row],[Month]]="March",3,IF(All_India_Index_Upto_April23__13[[#This Row],[Month]]="Marcrh",3,IF(All_India_Index_Upto_April23__13[[#This Row],[Month]]="April",4,IF(All_India_Index_Upto_April23__13[[#This Row],[Month]]="May",5,IF(All_India_Index_Upto_April23__13[[#This Row],[Month]]="June",6,IF(All_India_Index_Upto_April23__13[[#This Row],[Month]]="July",7,IF(All_India_Index_Upto_April23__13[[#This Row],[Month]]="August",8,IF(All_India_Index_Upto_April23__13[[#This Row],[Month]]="September",9,IF(All_India_Index_Upto_April23__13[[#This Row],[Month]]="October",10,IF(All_India_Index_Upto_April23__13[[#This Row],[Month]]="November",11,IF(All_India_Index_Upto_April23__13[[#This Row],[Month]]="December",12))))))))))))) -> 5
A124: Rural+Urban | B124: 2020 | C124: January | D124: =DATE(All_India_Index_Upto_April23__13[[#This Row],[Year]],All_India_Index_Upto_April23__13[[#This Row],[Month Number]],1) -> 43831 | E124: =IF(All_India_Index_Upto_April23__13[[#This Row],[Date]]<DATE(2020, 3, 1),"Pre-COVID","Post-COVID") -> Pre-COVID | F124: 144.3 | G124: 167.4 | H124: 154.9 | I124: 150.1 | J124: 129.9 | K124: 143.2 | L124: 197 | M124: 140.4 | N124: 114.1 | O124: 150.9 | P124: 136.1 | Q124: 158.6 | R124: 153.5 | S124: 169.2 | T124: 150.5 | U124: 141.5 | V124: 149.2 | W124: 153.9 | X124: 144.6 | Y124: 146.2 | Z124: 151.2 | AA124: 130.9 | AB124: 142.8 | AC124: 156.1 | AD124: 142.3 | AE124: 143.4 | AF124: 150.2 | AG124: =IF(All_India_Index_Upto_April23__13[[#This Row],[Month]] = "January", 1,IF(All_India_Index_Upto_April23__13[[#This Row],[Month]]="February",2,IF(All_India_Index_Upto_April23__13[[#This Row],[Month]]="March",3,IF(All_India_Index_Upto_April23__13[[#This Row],[Month]]="Marcrh",3,IF(All_India_Index_Upto_April23__13[[#This Row],[Month]]="April",4,IF(All_India_Index_Upto_April23__13[[#This Row],[Month]]="May",5,IF(All_India_Index_Upto_April23__13[[#This Row],[Month]]="June",6,IF(All_India_Index_Upto_April23__13[[#This Row],[Month]]="July",7,IF(All_India_Index_Upto_April23__13[[#This Row],[Month]]="August",8,IF(All_India_Index_Upto_April23__13[[#This Row],[Month]]="September",9,IF(All_India_Index_Upto_April23__13[[#This Row],[Month]]="October",10,IF(All_India_Index_Upto_April23__13[[#This Row],[Month]]="November",11,IF(All_India_Index_Upto_April23__13[[#This Row],[Month]]="December",12))))))))))))) -> 1
A125: Rural | B125: 2016 | C125: June | D125: =DATE(All_India_Index_Upto_April23__13[[#This Row],[Year]],All_India_Index_Upto_April23__13[[#This Row],[Month Number]],1) -> 42522 | E125: =IF(All_India_Index_Upto_April23__13[[#This Row],[Date]]<DATE(2020, 3, 1),"Pre-COVID","Post-COVID") -> Pre-COVID | F125: 128.6 | G125: 138.6 | H125: 126.6 | I125: 133.6 | J125: 118.6 | K125: 137.4 | L125: 152.5 | M125: 169.2 | N125: 108.8 | O125: 133.1 | P125: 126.4 | Q125: 139.2 | R125: 136 | S125: 137.2 | T125: 136.3 | U125: 131.6 | V125: 135.6 | W125: 141 | X125: 128 | Y125: 129.3 | Z125: 126.2 | AA125: 116.3 | AB125: 124.1 | AC125: 130.2 | AD125: 119.9 | AE125: 123.3 | AF125: 131.9 | AG125: =IF(All_India_Index_Upto_April23__13[[#This Row],[Month]] = "January", 1,IF(All_India_Index_Upto_April23__13[[#This Row],[Month]]="February",2,IF(All_India_Index_Upto_April23__13[[#This Row],[Month]]="March",3,IF(All_India_Index_Upto_April23__13[[#This Row],[Month]]="Marcrh",3,IF(All_India_Index_Upto_April23__13[[#This Row],[Month]]="April",4,IF(All_India_Index_Upto_April23__13[[#This Row],[Month]]="May",5,IF(All_India_Index_Upto_April23__13[[#This Row],[Month]]="June",6,IF(All_India_Index_Upto_April23__13[[#This Row],[Month]]="July",7,IF(All_India_Index_Upto_April23__13[[#This Row],[Month]]="August",8,IF(All_India_Index_Upto_April23__13[[#This Row],[Month]]="September",9,IF(All_India_Index_Upto_April23__13[[#This Row],[Month]]="October",10,IF(All_India_Index_Upto_April23__13[[#This Row],[Month]]="November",11,IF(All_India_Index_Upto_April23__13[[#This Row],[Month]]="December",12))))))))))))) -> 6
A126: Urban | B126: 2016 | C126: June | D126: =DATE(All_India_Index_Upto_April23__13[[#This Row],[Year]],All_India_Index_Upto_April23__13[[#This Row],[Month Number]],1) -> 42522 | E126: =IF(All_India_Index_Upto_April23__13[[#This Row],[Date]]<DATE(2020, 3, 1),"Pre-COVID","Post-COVID") -> Pre-COVID | F126: 125.9 | G126: 143.9 | H126: 130.9 | I126: 131 | J126: 110.2 | K126: 135.5 | L126: 173.7 | M126: 184.4 | N126: 112 | O126: 142.8 | P126: 121.6 | Q126: 136.9 | R126: 138.2 | S126: 142.7 | T126: 127.6 | U126: 121.1 | V126: 126.6 | W126: 125.5 | X126: 115.5 | Y126: 123.2 | Z126: 120.6 | AA126: 112.3 | AB126: 119.9 | AC126: 129.3 | AD126: 118.8 | AE126: 119.6 | AF126: 128.1 | AG126: =IF(All_India_Index_Upto_April23__13[[#This Row],[Month]] = "January", 1,IF(All_India_Index_Upto_April23__13[[#This Row],[Month]]="February",2,IF(All_India_Index_Upto_April23__13[[#This Row],[Month]]="March",3,IF(All_India_Index_Upto_April23__13[[#This Row],[Month]]="Marcrh",3,IF(All_India_Index_Upto_April23__13[[#This Row],[Month]]="April",4,IF(All_India_Index_Upto_April23__13[[#This Row],[Month]]="May",5,IF(All_India_Index_Upto_April23__13[[#This Row],[Month]]="June",6,IF(All_India_Index_Upto_April23__13[[#This Row],[Month]]="July",7,IF(All_India_Index_Upto_April23__13[[#This Row],[Month]]="August",8,IF(All_India_Index_Upto_April23__13[[#This Row],[Month]]="September",9,IF(All_India_Index_Upto_April23__13[[#This Row],[Month]]="October",10,IF(All_India_Index_Upto_April23__13[[#This Row],[Month]]="November",11,IF(All_India_Index_Upto_April23__13[[#This Row],[Month]]="December",12))))))))))))) -> 6
A127: Rural+Urban | B127: 2019 | C127: December | D127: =DATE(All_India_Index_Upto_April23__13[[#This Row],[Year]],All_India_Index_Upto_April23__13[[#This Row],[Month Number]],1) -> 43800 | E127: =IF(All_India_Index_Upto_April23__13[[#This Row],[Date]]<DATE(2020, 3, 1),"Pre-COVID","Post-COVID") -> Pre-COVID | F127: 143.5 | G127: 165 | H127: 151.1 | I127: 148.3 | J127: 125.7 | K127: 145.7 | L127: 217 | M127: 138.3 | N127: 114 | O127: 148.7 | P127: 135.8 | Q127: 158 | R127: 155 | S127: 168.5 | T127: 150.3 | U127: 141.3 | V127: 149 | W127: 152.8 | X127: 143.7 | Y127: 145.8 | Z127: 150.4 | AA127: 129.8 | AB127: 142.3 | AC127: 155.7 | AD127: 140.4 | AE127: 142.5 | AF127: 150.4 | AG127: =IF(All_India_Index_Upto_April23__13[[#This Row],[Month]] = "January", 1,IF(All_India_Index_Upto_April23__13[[#This Row],[Month]]="February",2,IF(All_India_Index_Upto_April23__13[[#This Row],[Month]]="March",3,IF(All_India_Index_Upto_April23__13[[#This Row],[Month]]="Marcrh",3,IF(All_India_Index_Upto_April23__13[[#This Row],[Month]]="April",4,IF(All_India_Index_Upto_April23__13[[#This Row],[Month]]="May",5,IF(All_India_Index_Upto_April23__13[[#This Row],[Month]]="June",6,IF(All_India_Index_Upto_April23__13[[#This Row],[Month]]="July",7,IF(All_India_Index_Upto_April23__13[[#This Row],[Month]]="August",8,IF(All_India_Index_Upto_April23__13[[#This Row],[Month]]="September",9,IF(All_India_Index_Upto_April23__13[[#This Row],[Month]]="October",10,IF(All_India_Index_Upto_April23__13[[#This Row],[Month]]="November",11,IF(All_India_Index_Upto_April23__13[[#This Row],[Month]]="December",12))))))))))))) -> 12
... A259: Rural+Urban | B259: 2016 | C259: March | D259: =DATE(All_India_Index_Upto_April23__13[[#This Row],[Year]],All_India_Index_Upto_April23__13[[#This Row],[Month Number]],1) -> 42430 | E259: =IF(All_India_Index_Upto_April23__13[[#This Row],[Date]]<DATE(2020, 3, 1),"Pre-COVID","Post-COVID") -> Pre-COVID | F259: 126.5 | G259: 135.1 | H259: 124.6 | I259: 130.2 | J259: 114.5 | K259: 126.2 | L259: 129.8 | M259: 164.3 | N259: 100.9 | O259: 133.9 | P259: 123.1 | Q259: 136.3 | R259: 129.8 | S259: 136.5 | T259: 131.3 | U259: 126.1 | V259: 130.5 | W259: 124.9 | X259: 122.4 | Y259: 125.1 | Z259: 122.9 | AA259: 110.9 | AB259: 120.6 | AC259: 126.9 | AD259: 117.3 | AE259: 119.3 | AF259: 126 | AG259: =IF(All_India_Index_Upto_April23__13[[#This Row],[Month]] = "January", 1,IF(All_India_Index_Upto_April23__13[[#This Row],[Month]]="February",2,IF(All_India_Index_Upto_April23__13[[#This Row],[Month]]="March",3,IF(All_India_Index_Upto_April23__13[[#This Row],[Month]]="Marcrh",3,IF(All_India_Index_Upto_April23__13[[#This Row],[Month]]="April",4,IF(All_India_Index_Upto_April23__13[[#This Row],[Month]]="May",5,IF(All_India_Index_Upto_April23__13[[#This Row],[Month]]="June",6,IF(All_India_Index_Upto_April23__13[[#This Row],[Month]]="July",7,IF(All_India_Index_Upto_April23__13[[#This Row],[Month]]="August",8,IF(All_India_Index_Upto_April23__13[[#This Row],[Month]]="September",9,IF(All_India_Index_Upto_April23__13[[#This Row],[Month]]="October",10,IF(All_India_Index_Upto_April23__13[[#This Row],[Month]]="November",11,IF(All_India_Index_Upto_April23__13[[#This Row],[Month]]="December",12))))))))))))) -> 3
A260: Rural | B260: 2020 | C260: April | D260: =DATE(All_India_Index_Upto_April23__13[[#This Row],[Year]],All_India_Index_Upto_April23__13[[#This Row],[Month Number]],1) -> 43922 | E260: =IF(All_India_Index_Upto_April23__13[[#This Row],[Date]]<DATE(2020, 3, 1),"Pre-COVID","Post-COVID") -> Post-COVID | F260: 147.2 | G260: ='Missing Values Handled'!$H$8 -> 144.2 | H260: 146.9 | I260: 155.6 | J260: 137.1 | K260: 147.3 | L260: 162.7 | M260: 150.2 | N260: 119.8 | O260: 158.7 | P260: 139.2 | Q260: ='Missing Values Handled'!R$8 -> 135.5 | R260: 150.1 | S260: ='Missing Values Handled'!T$8 -> 144.2 | T260: ='Missing Values Handled'!U$8 -> 135.5 | U260: ='Missing Values Handled'!V$8 -> 141 | V260: ='Missing Values Handled'!W$8 -> 135.5 | W260: 141 | X260: 148.4 | Y260: ='Missing Values Handled'!Z$8 -> 144.2 | Z260: 154.3 | AA260: ='Missing Values Handled'!AB$8 -> 141 | AB260: ='Missing Values Handled'!AC$8 -> 135.5 | AC260: ='Missing Values Handled'!AD$8 -> 141 | AD260: ='Missing Values Handled'!AE$8 -> 144.2 | AE260: ='Missing Values Handled'!AF$8 -> 135.5 | AF260: ='Missing Values Handled'!AG$8 -> 141 | AG260: =IF(All_India_Index_Upto_April23__13[[#This Row],[Month]] = "January", 1,IF(All_India_Index_Upto_April23__13[[#This Row],[Month]]="February",2,IF(All_India_Index_Upto_April23__13[[#This Row],[Month]]="March",3,IF(All_India_Index_Upto_April23__13[[#This Row],[Month]]="Marcrh",3,IF(All_India_Index_Upto_April23__13[[#This Row],[Month]]="April",4,IF(All_India_Index_Upto_April23__13[[#This Row],[Month]]="May",5,IF(All_India_Index_Upto_April23__13[[#This Row],[Month]]="June",6,IF(All_India_Index_Upto_April23__13[[#This Row],[Month]]="July",7,IF(All_India_Index_Upto_April23__13[[#This Row],[Month]]="August",8,IF(All_India_Index_Upto_April23__13[[#This Row],[Month]]="September",9,IF(All_India_Index_Upto_April23__13[[#This Row],[Month]]="October",10,IF(All_India_Index_Upto_April23__13[[#This Row],[Month]]="November",11,IF(All_India_Index_Upto_April23__13[[#This Row],[Month]]="December",12))))))))))))) -> 4
A261: Urban | B261: 2020 | C261: April | D261: =DATE(All_India_Index_Upto_April23__13[[#This Row],[Year]],All_India_Index_Upto_April23__13[[#This Row],[Month Number]],1) -> 43922 | E261: =IF(All_India_Index_Upto_April23__13[[#This Row],[Date]]<DATE(2020, 3, 1),"Pre-COVID","Post-COVID") -> Post-COVID | F261: 151.8 | G261: ='Missing Values Handled'!$H$8 -> 144.2 | H261: 151.9 | I261: 155.5 | J261: 131.6 | K261: 152.9 | L261: 180 | M261: 150.8 | N261: 121.2 | O261: 154 | P261: 133.5 | Q261: ='Missing Values Handled'!R$8 -> 135.5 | R261: 153.5 | S261: ='Missing Values Handled'!T$8 -> 144.2 | T261: ='Missing Values Handled'!U$8 -> 135.5 | U261: ='Missing Values Handled'!V$8 -> 141 | V261: ='Missing Values Handled'!W$8 -> 135.5 | W261: 155.6 | X261: 137.1 | Y261: ='Missing Values Handled'!Z$8 -> 144.2 | Z261: 144.8 | AA261: ='Missing Values Handled'!AB$8 -> 141 | AB261: ='Missing Values Handled'!AC$8 -> 135.5 | AC261: ='Missing Values Handled'!AD$8 -> 141 | AD261: ='Missing Values Handled'!AE$8 -> 144.2 | AE261: ='Missing Values Handled'!AF$8 -> 135.5 | AF261: ='Missing Values Handled'!AG$8 -> 141 | AG261: =IF(All_India_Index_Upto_April23__13[[#This Row],[Month]] = "January", 1,IF(All_India_Index_Upto_April23__13[[#This Row],[Month]]="February",2,IF(All_India_Index_Upto_April23__13[[#This Row],[Month]]="March",3,IF(All_India_Index_Upto_April23__13[[#This Row],[Month]]="Marcrh",3,IF(All_India_Index_Upto_April23__13[[#This Row],[Month]]="April",4,IF(All_India_Index_Upto_April23__13[[#This Row],[Month]]="May",5,IF(All_India_Index_Upto_April23__13[[#This Row],[Month]]="June",6,IF(All_India_Index_Upto_April23__13[[#This Row],[Month]]="July",7,IF(All_India_Index_Upto_April23__13[[#This Row],[Month]]="August",8,IF(All_India_Index_Upto_April23__13[[#This Row],[Month]]="September",9,IF(All_India_Index_Upto_April23__13[[#This Row],[Month]]="October",10,IF(All_India_Index_Upto_April23__13[[#This Row],[Month]]="November",11,IF(All_India_Index_Upto_April23__13[[#This Row],[Month]]="December",12))))))))))))) -> 4
A262: Rural+Urban | B262: 2016 | C262: February | D262: =DATE(All_India_Index_Upto_April23__13[[#This Row],[Year]],All_India_Index_Upto_April23__13[[#This Row],[Month Number]],1) -> 42401 | E262: =IF(All_India_Index_Upto_April23__13[[#This Row],[Date]]<DATE(2020, 3, 1),"Pre-COVID","Post-COVID") -> Pre-COVID | F262: 126.4 | G262: 134.2 | H262: 128.7 | I262: 130.3 | J262: 114.8 | K262: 124.9 | L262: 130.3 | M262: 167.4 | N262: 98.8 | O262: 133.6 | P262: 123 | Q262: 135.8 | R262: 129.9 | S262: 135.9 | T262: 130.9 | U262: 125.8 | V262: 130.2 | W262: 124.4 | X262: 123.1 | Y262: 124.6 | Z262: 122.5 | AA262: 111.4 | AB262: 120.3 | AC262: 126.6 | AD262: 116.6 | AE262: 119.1 | AF262: 126 | AG262: =IF(All_India_Index_Upto_April23__13[[#This Row],[Month]] = "January", 1,IF(All_India_Index_Upto_April23__13[[#This Row],[Month]]="February",2,IF(All_India_Index_Upto_April23__13[[#This Row],[Month]]="March",3,IF(All_India_Index_Upto_April23__13[[#This Row],[Month]]="Marcrh",3,IF(All_India_Index_Upto_April23__13[[#This Row],[Month]]="April",4,IF(All_India_Index_Upto_April23__13[[#This Row],[Month]]="May",5,IF(All_India_Index_Upto_April23__13[[#This Row],[Month]]="June",6,IF(All_India_Index_Upto_April23__13[[#This Row],[Month]]="July",7,IF(All_India_Index_Upto_April23__13[[#This Row],[Month]]="August",8,IF(All_India_Index_Upto_April23__13[[#This Row],[Month]]="September",9,IF(All_India_Index_Upto_April23__13[[#This Row],[Month]]="October",10,IF(All_India_Index_Upto_April23__13[[#This Row],[Month]]="November",11,IF(All_India_Index_Upto_April23__13[[#This Row],[Month]]="December",12))))))))))))) -> 2
A263: Rural | B263: 2020 | C263: May | D263: =DATE(All_India_Index_Upto_April23__13[[#This Row],[Year]],All_India_Index_Upto_April23__13[[#This Row],[Month Number]],1) -> 43952 | E263: =IF(All_India_Index_Upto_April23__13[[#This Row],[Date]]<DATE(2020, 3, 1),"Pre-COVID","Post-COVID") -> Post-COVID | F263: =VALUE('Missing Values Handled'!$G$8) -> 135.9 | G263: ='Missing Values Handled'!$H$8 -> 144.2 | H263: ='Missing Values Handled'!I$8 -> 135.5 | I263: ='Missing Values Handled'!J$8 -> 144.2 | J263: ='Missing Values Handled'!K$8 -> 135.5 | K263: ='Missing Values Handled'!L$8 -> 141 | L263: ='Missing Values Handled'!M$8 -> 135.5 | M263: ='Missing Values Handled'!N$8 -> 141 | N263: ='Missing Values Handled'!O$8 -> 120.5 | O263: ='Missing Values Handled'!P$8 -> 141 | ... V263: ='Missing Values Handled'!W$8 -> 135.5 | W263: 141 | X263: ='Missing Values Handled'!Y$8 -> 120.5 | Y263: ='Missing Values Handled'!Z$8 -> 144.2 | Z263: ='Missing Values Handled'!AA$8 -> 135.5 | AA263: ='Missing Values Handled'!AB$8 -> 141 | AB263: ='Missing Values Handled'!AC$8 -> 135.5 | AC263: ='Missing Values Handled'!AD$8 -> 141 | AD263: ='Missing Values Handled'!AE$8 -> 144.2 | AE263: ='Missing Values Handled'!AF$8 -> 135.5 | AF263: ='Missing Values Handled'!AG$8 -> 141 | AG263: =IF(All_India_Index_Upto_April23__13[[#This Row],[Month]] = "January", 1,IF(All_India_Index_Upto_April23__13[[#This Row],[Month]]="February",2,IF(All_India_Index_Upto_April23__13[[#This Row],[Month]]="March",3,IF(All_India_Index_Upto_April23__13[[#This Row],[Month]]="Marcrh",3,IF(All_India_Index_Upto_April23__13[[#This Row],[Month]]="April",4,IF(All_India_Index_Upto_April23__13[[#This Row],[Month]]="May",5,IF(All_India_Index_Upto_April23__13[[#This Row],[Month]]="June",6,IF(All_India_Index_Upto_April23__13[[#This Row],[Month]]="July",7,IF(All_India_Index_Upto_April23__13[[#This Row],[Month]]="August",8,IF(All_India_Index_Upto_April23__13[[#This Row],[Month]]="September",9,IF(All_India_Index_Upto_April23__13[[#This Row],[Month]]="October",10,IF(All_India_Index_Upto_April23__13[[#This Row],[Month]]="November",11,IF(All_India_Index_Upto_April23__13[[#This Row],[Month]]="December",12))))))))))))) -> 5
A264: Urban | B264: 2020 | C264: May | D264: =DATE(All_India_Index_Upto_April23__13[[#This Row],[Year]],All_India_Index_Upto_April23__13[[#This Row],[Month Number]],1) -> 43952 | E264: =IF(All_India_Index_Upto_April23__13[[#This Row],[Date]]<DATE(2020, 3, 1),"Pre-COVID","Post-COVID") -> Post-COVID | F264: =VALUE('Missing Values Handled'!$G$8) -> 135.9 | G264: ='Missing Values Handled'!$H$8 -> 144.2 | H264: ='Missing Values Handled'!$I$8 -> 135.5 | I264: ='Missing Values Handled'!J$8 -> 144.2 | J264: ='Missing Values Handled'!K$8 -> 135.5 | K264: ='Missing Values Handled'!L$8 -> 141 | L264: ='Missing Values Handled'!M$8 -> 135.5 | M264: ='Missing Values Handled'!N$8 -> 141 | N264: ='Missing Values Handled'!O$8 -> 120.5 | O264: ='Missing Values Handled'!P$8 -> 141 | P264: ='Missing Values Handled'!Q$8 -> 144.2 | ... V264: ='Missing Values Handled'!W$8 -> 135.5 | W264: 141 | X264: ='Missing Values Handled'!Y$8 -> 120.5 | Y264: ='Missing Values Handled'!Z$8 -> 144.2 | Z264: ='Missing Values Handled'!AA$8 -> 135.5 | AA264: ='Missing Values Handled'!AB$8 -> 141 | AB264: ='Missing Values Handled'!AC$8 -> 135.5 | AC264: ='Missing Values Handled'!AD$8 -> 141 | AD264: ='Missing Values Handled'!AE$8 -> 144.2 | AE264: ='Missing Values Handled'!AF$8 -> 135.5 | AF264: ='Missing Values Handled'!AG$8 -> 141 | AG264: =IF(All_India_Index_Upto_April23__13[[#This Row],[Month]] = "January", 1,IF(All_India_Index_Upto_April23__13[[#This Row],[Month]]="February",2,IF(All_India_Index_Upto_April23__13[[#This Row],[Month]]="March",3,IF(All_India_Index_Upto_April23__13[[#This Row],[Month]]="Marcrh",3,IF(All_India_Index_Upto_April23__13[[#This Row],[Month]]="April",4,IF(All_India_Index_Upto_April23__13[[#This Row],[Month]]="May",5,IF(All_India_Index_Upto_April23__13[[#This Row],[Month]]="June",6,IF(All_India_Index_Upto_April23__13[[#This Row],[Month]]="July",7,IF(All_India_Index_Upto_April23__13[[#This Row],[Month]]="August",8,IF(All_India_Index_Upto_April23__13[[#This Row],[Month]]="September",9,IF(All_India_Index_Upto_April23__13[[#This Row],[Month]]="October",10,IF(All_India_Index_Upto_April23__13[[#This Row],[Month]]="November",11,IF(All_India_Index_Upto_April23__13[[#This Row],[Month]]="December",12))))))))))))) -> 5
